scripts/test_case1.txt
40
0 o
1 o
2 o
3 o
4 o
5 o
6 o
7 o
8 o
9 o
10 o
11 o
12 o
13 o
14 o
15 o
16 o
17 o
18 o
19 o
20 o
21 o
22 o
23 o
24 o
25 o
26 o
27 o
28 o
29 o
30 o
31 o
32 o
33 o
34 o
35 o
36 o
37 o
38 o
39 o
.
38 S 7583639 MSFT 53120 5885
37 S 4574731 GOOG 46216 9422
32 S 90565544 AMZN 86183 9692
38 C 7583639
38 S 50504913 GOOG 32530 5441
38 S 69932372 AMZN 95542 5539
35 S 179137 AMZN 44282 3058
39 B 59630219 AAPL 78710 6913
39 C 59630219
38 S 43938163 MSFT 68360 4221
38 C 69932372
39 C 59630219
39 B 12495637 MSFT 40961 6315
39 S 44790165 AMZN 64775 7385
39 S 69861806 AMZN 78356 9049
38 C 50504913
37 S 75714631 MSFT 1652 7073
39 S 41040536 AAPL 69386 3143
38 S 99423844 GOOG 57978 7099
38 S 51320031 MSFT 27372 3345
39 C 41040536
39 C 44790165
38 B 12381152 AAPL 5260 1228
38 B 52969359 AMZN 91211 776
39 C 41040536
39 B 86809898 MSFT 63554 9716
37 S 64506425 AAPL 95197 1806
38 C 12381152
37 S 22687185 MSFT 34998 7355
39 S 51865896 AMZN 23798 7669
39 C 12495637
35 S 26416160 MSFT 96982 9623
39 B 79034340 MSFT 84623 9830
38 B 14863170 GOOG 81158 6742
39 C 41040536
39 B 91870640 AMZN 28783 4970
39 C 91870640
37 S 75496752 AAPL 78974 7698
37 C 22687185
39 S 97123410 AMZN 73771 2237
39 S 76640202 AAPL 45268 8262
39 B 11532432 AAPL 12255 4669
39 C 11532432
39 S 74856621 GOOG 20131 2190
39 B 57707631 AAPL 50088 3960
38 S 12146515 AMZN 78949 2654
39 C 11532432
39 C 41040536
37 S 18894204 AAPL 51544 6553
37 B 13119465 GOOG 91237 5296
39 C 97123410
37 B 9756104 AMZN 60412 3600
39 C 74856621
36 S 14173639 GOOG 24058 2849
39 S 28699877 AMZN 5085 6672
36 B 79875571 AAPL 62301 7911
38 B 52344205 MSFT 48499 5259
39 S 71270015 GOOG 90776 6525
38 B 89329850 MSFT 20432 568
37 C 18894204
38 S 89468136 MSFT 96377 7334
37 S 46213371 AAPL 86741 2328
36 C 14173639
36 B 38555211 MSFT 51819 9948
39 C 79034340
39 C 41040536
39 S 78184022 AMZN 62241 4246
39 S 1810845 AMZN 98346 1067
39 C 71270015
36 C 14173639
38 B 52390228 AAPL 47619 9895
38 B 78940344 AMZN 79558 6653
39 S 99878509 AMZN 76295 5985
39 C 11532432
39 B 6492036 MSFT 78691 950
39 B 75970086 AAPL 92028 4993
39 B 92663841 AMZN 22582 6234
39 C 69861806
39 B 83111165 MSFT 87901 6381
39 S 82127906 MSFT 74355 1396
39 B 73374290 GOOG 96207 3882
39 B 22955218 GOOG 45830 5312
38 S 7659059 GOOG 23767 4367
39 C 75970086
39 C 92663841
39 B 4732208 GOOG 84407 2377
39 B 17802052 GOOG 11580 9501
39 S 25016734 AAPL 38834 4013
38 C 43938163
38 S 87741084 AMZN 39105 7449
39 C 69861806
35 B 25917298 AMZN 87462 3478
38 B 68261538 AMZN 28103 5310
38 B 14509146 GOOG 1486 8241
39 S 41140720 AAPL 78622 9761
38 C 52344205
35 B 9351655 AAPL 2683 630
39 C 12495637
39 S 74137 MSFT 96160 8598
39 C 79034340
35 B 45437344 GOOG 41396 1865
39 C 86809898
37 B 8732045 AMZN 77853 1334
36 S 2961496 AMZN 10562 9745
38 B 25314593 GOOG 87172 9596
39 C 79034340
38 B 2097573 AMZN 49288 660
35 C 9351655
38 S 65268496 GOOG 61309 711
39 C 22955218
39 S 18725287 MSFT 64620 6029
38 C 7583639
38 S 96678064 GOOG 94854 9733
36 C 38555211
37 S 14076701 AMZN 64817 3403
38 S 7276993 GOOG 21061 2864
39 C 12495637
36 C 38555211
39 B 17304110 AAPL 21751 4686
39 S 50455636 MSFT 4502 6724
37 B 71038829 GOOG 46252 854
35 S 683279 MSFT 90869 6260
39 C 22955218
39 C 74856621
38 S 61453990 MSFT 56692 3492
38 S 73012091 AMZN 51933 124
38 C 73012091
37 C 22687185
38 C 14863170
39 C 69861806
37 C 9756104
38 S 24986052 MSFT 58947 2572
38 B 95782100 AAPL 77370 15
39 S 78350866 MSFT 33109 197
39 C 99878509
39 B 94692505 MSFT 63609 2531
39 B 42661208 AMZN 8201 3200
38 B 28500386 MSFT 45496 4137
39 B 86661407 GOOG 53104 5913
38 B 88341021 GOOG 12278 4219
39 C 6492036
39 S 27960363 AAPL 82791 4439
36 S 63818218 MSFT 56301 8040
39 C 6492036
39 B 26193040 GOOG 30490 6141
39 B 47906572 AMZN 99423 8633
31 B 1561176 AMZN 63224 233
39 B 62528790 AMZN 1421 3721
39 S 9408403 AAPL 75081 2539
39 B 52677524 AAPL 81815 8038
37 C 14076701
39 B 51569900 GOOG 86529 4230
39 S 17593246 AMZN 77255 6783
39 S 69994723 AMZN 7710 1185
39 S 52823466 AMZN 29820 8098
38 S 13280134 GOOG 39463 3448
35 S 59630071 MSFT 37671 3276
38 B 24143256 AMZN 36085 166
30 S 69569743 GOOG 2377 5319
39 S 2885225 GOOG 49128 9040
39 S 68947369 MSFT 67395 1504
37 C 13119465
39 C 69994723
39 S 85063315 GOOG 87067 4052
38 S 8199336 AAPL 90052 3942
39 C 44790165
39 B 29835734 AMZN 41064 3003
39 C 92663841
39 B 4489702 MSFT 6974 9796
39 S 67797878 AAPL 92562 2836
39 C 17802052
38 S 44402354 MSFT 77934 809
37 B 95752522 AAPL 16678 8129
39 C 4732208
39 C 18725287
38 S 29576635 GOOG 35101 8831
37 B 3728348 AAPL 62303 90
38 B 70540856 GOOG 35883 7238
39 C 86661407
39 B 82224737 GOOG 62733 5466
38 C 25314593
39 B 45386369 AAPL 79812 9669
38 S 55937313 GOOG 83316 2565
39 B 65829099 AMZN 60024 6063
38 B 64712178 GOOG 63919 8524
39 S 85446378 GOOG 98016 5204
39 S 11250079 GOOG 49768 1008
38 S 62245007 AMZN 39676 3517
39 S 34836949 AAPL 95211 4102
38 C 78940344
38 C 25314593
37 S 61119473 MSFT 48547 5353
38 B 82209676 AMZN 89333 1496
35 S 41057045 AAPL 22345 9457
35 C 59630071
34 B 741480 AMZN 57715 7561
34 S 93241130 GOOG 33221 1273
38 S 74366152 GOOG 92181 6241
38 C 29576635
38 B 19447874 GOOG 20198 3719
38 B 6633441 AMZN 73360 165
38 S 31918266 GOOG 21859 70
38 S 31204978 AMZN 28378 3773
33 B 55305660 AAPL 62813 9682
38 C 73012091
38 C 99423844
38 S 58417994 MSFT 37348 3259
38 B 95014120 MSFT 35941 2337
35 B 44098643 GOOG 35715 2119
38 C 31204978
38 C 61453990
37 C 64506425
37 C 75714631
38 C 28500386
37 S 2467932 AAPL 46053 8081
37 S 39671194 MSFT 14721 8447
38 B 97823485 AMZN 44702 2671
37 B 76645302 MSFT 76042 4420
35 S 51489729 AAPL 73191 6519
35 C 45437344
38 C 78940344
38 B 49562737 AMZN 38454 7405
37 B 36077149 MSFT 2714 5076
38 S 49761921 MSFT 77089 6946
38 B 91402653 AAPL 53202 9507
38 C 61453990
37 S 5394406 GOOG 48692 6135
33 B 1229455 GOOG 10511 5029
36 S 82593870 GOOG 24556 4332
38 B 49867308 GOOG 50070 3303
35 S 56791997 GOOG 82625 7548
38 S 36664036 GOOG 78996 179
38 S 560702 AAPL 20528 4265
38 S 11998659 AAPL 22136 1872
32 C 90565544
37 S 69569921 AAPL 89874 5104
38 B 78296712 AAPL 17572 114
37 C 18894204
37 S 79785440 AMZN 2457 5003
35 B 46967112 MSFT 52048 8545
37 S 67788237 GOOG 72700 4042
37 C 75496752
38 S 64044637 GOOG 54882 3000
38 C 29576635
38 B 53303060 GOOG 79393 9246
37 C 4574731
38 B 11802266 MSFT 6397 2022
38 S 77956633 AAPL 24634 1759
38 S 37854734 AAPL 50737 1134
38 C 95014120
38 C 12146515
38 C 52390228
38 C 99423844
38 S 38632570 AMZN 3632 1859
38 C 36664036
38 C 50504913
37 S 1621129 MSFT 60747 9340
37 B 85223041 AMZN 21626 2583
37 C 46213371
36 S 47841906 MSFT 4002 5576
37 S 36686757 AMZN 59858 2255
37 B 7412400 GOOG 37703 9909
35 C 45437344
37 S 57120980 AMZN 62944 1463
37 C 2467932
35 S 89830313 AAPL 27943 7011
38 S 17782643 GOOG 16607 5033
37 C 61119473
38 S 95324806 MSFT 36717 8092
37 B 33140998 AMZN 80018 5914
37 C 18894204
38 B 75774747 AAPL 20379 8588
36 B 53230161 GOOG 46635 102
36 C 2961496
37 B 22319828 AMZN 16937 4404
37 B 71497479 GOOG 95108 7261
38 B 95693853 MSFT 70313 9021
38 C 44402354
38 B 48516496 AAPL 42597 604
35 B 10546296 AAPL 24941 2929
38 C 69932372
38 B 73612601 AAPL 37279 8418
38 C 52390228
35 B 55598440 AMZN 64746 2144
38 B 89663643 GOOG 40552 5888
38 B 60439049 MSFT 83518 983
36 C 14173639
35 S 68404522 GOOG 54148 9636
37 C 95752522
35 C 59630071
37 B 80486936 MSFT 82898 5174
37 S 38509164 AAPL 11169 5100
37 S 9442036 AAPL 55697 3376
37 S 94809401 AAPL 74967 4594
34 B 83618038 MSFT 90741 5435
35 C 26416160
34 B 47631248 MSFT 96260 3720
36 B 25014354 AAPL 84758 2855
37 B 33619200 AAPL 79099 2535
37 B 5682012 GOOG 90704 6289
37 B 93918078 MSFT 81651 9225
37 S 57092652 GOOG 25958 8014
36 B 94890581 MSFT 84465 9877
37 B 35736073 GOOG 97656 6434
35 S 9396354 AAPL 25931 1699
36 C 2961496
37 S 12160801 AMZN 79157 7683
37 C 95752522
37 B 61347414 AAPL 27193 3433
37 C 36077149
29 S 3509692 GOOG 84051 2338
37 C 33619200
37 C 12160801
37 S 32362311 AMZN 18423 7773
37 S 90307207 GOOG 38215 6086
37 B 85856458 AMZN 40408 14
37 B 10741422 GOOG 57862 4768
34 S 86146573 GOOG 76183 1623
36 S 9264212 AMZN 51979 9993
