scripts/test_case10.txt
40
0 o
1 o
2 o
3 o
4 o
5 o
6 o
7 o
8 o
9 o
10 o
11 o
12 o
13 o
14 o
15 o
16 o
17 o
18 o
19 o
20 o
21 o
22 o
23 o
24 o
25 o
26 o
27 o
28 o
29 o
30 o
31 o
32 o
33 o
34 o
35 o
36 o
37 o
38 o
39 o
.
37 S 93968227 AMZN 93592 7005
34 S 72079546 AAPL 21919 2349
39 S 93094838 AMZN 58843 5361
38 S 7813700 AAPL 1552 5285
39 S 89749790 AMZN 1363 2689
39 B 65390459 AAPL 10768 5891
38 C 7813700
39 B 18581424 GOOG 52911 5594
39 C 65390459
38 S 45227050 MSFT 63475 6311
37 B 15672842 MSFT 85364 6846
39 C 18581424
34 S 40067901 MSFT 80308 5504
39 S 12454796 GOOG 63471 1425
35 S 45758146 MSFT 57164 8842
37 B 93090092 AAPL 38586 5855
36 B 38488313 AAPL 52630 239
38 C 45227050
38 S 11180355 AAPL 80165 2502
39 B 11353920 AAPL 83308 6923
39 C 65390459
38 B 48271922 AMZN 40171 1856
37 C 93090092
38 B 18552125 MSFT 13407 8503
39 S 79329594 AAPL 81066 3734
35 B 3247402 GOOG 17302 4830
39 S 78773734 MSFT 54223 1929
35 S 71687731 AAPL 61073 6322
38 S 76592222 AAPL 77592 1641
39 S 48863279 MSFT 63847 5235
38 C 48271922
37 C 93968227
38 B 82383658 AAPL 67045 9847
39 B 67661818 GOOG 67754 113
39 B 70569828 AMZN 80125 7086
39 S 10165501 MSFT 68529 6665
37 B 17432355 AAPL 65914 4701
37 S 18478497 AAPL 47018 919
39 B 98944135 MSFT 12228 1241
39 C 70569828
38 C 11180355
37 B 17379488 AAPL 62336 8014
39 C 48863279
39 C 12454796
36 B 4655974 AMZN 88340 4583
39 S 81930179 AMZN 81751 518
38 C 82383658
37 S 50770799 MSFT 85624 8794
39 S 97264747 AAPL 76396 7550
39 C 18581424
38 C 82383658
37 S 72608991 GOOG 13609 2822
39 B 37691347 MSFT 42774 7583
39 C 18581424
36 B 65932423 MSFT 52309 6510
37 S 15216862 GOOG 84506 2000
39 S 56025615 MSFT 82776 4787
39 S 92976695 MSFT 38479 7624
39 S 85966742 AMZN 67778 6892
39 B 47824737 AMZN 67806 5242
38 S 43598460 AAPL 78295 9660
38 C 43598460
38 S 9627308 GOOG 44663 5064
39 B 73135746 GOOG 40519 2767
36 C 4655974
39 S 45550145 MSFT 6118 5708
38 S 26805532 AMZN 85086 403
39 B 90857339 AAPL 39259 9813
38 C 7813700
38 C 43598460
38 C 43598460
38 B 97928113 MSFT 90135 2046
39 S 85789357 AAPL 48985 2780
37 S 64557516 AMZN 24264 3182
38 C 18552125
37 B 91772595 MSFT 81574 3723
38 B 63265898 MSFT 32019 5031
39 B 77443423 AAPL 95679 3667
36 C 65932423
38 S 68178801 GOOG 61906 5705
39 B 10785154 AAPL 61020 7533
39 C 18581424
39 C 98944135
37 C 64557516
39 C 10165501
38 B 35431794 AMZN 92568 4121
39 C 92976695
39 C 97264747
34 S 74083672 AMZN 67402 1011
37 B 50404154 AMZN 35083 1378
39 S 7513440 GOOG 91832 2206
38 C 18552125
36 B 97787481 AAPL 89121 7095
39 C 89749790
39 C 70569828
39 S 32363514 MSFT 73549 401
38 S 22458301 AAPL 56511 9658
38 S 33678919 AMZN 2035 2586
39 B 73481118 AAPL 51339 5592
39 B 77613817 AAPL 92175 1918
39 C 10165501
38 C 18552125
33 S 40494233 MSFT 22247 2345
39 C 90857339
33 B 30350262 AMZN 58485 7862
39 S 98910157 MSFT 82053 5280
38 B 77567175 GOOG 16040 3417
39 B 57526647 AAPL 43220 2144
37 B 5675607 AAPL 52335 5662
36 S 28517957 AAPL 41003 1734
37 C 91772595
36 S 70337147 GOOG 15685 1008
38 C 68178801
39 S 46241833 MSFT 86548 9131
37 B 13282829 GOOG 33258 3856
38 C 18552125
39 C 32363514
38 B 73253258 GOOG 10690 9087
39 B 88087947 MSFT 53873 9424
39 S 19863451 GOOG 64056 1260
39 C 70569828
37 B 38632774 AMZN 21174 1635
39 S 57055978 GOOG 58047 8421
39 S 30759854 GOOG 40103 8479
38 C 33678919
38 S 37451050 AAPL 67065 8833
35 B 33801770 MSFT 50735 5304
36 S 99809020 AMZN 71355 3168
39 B 9622824 AMZN 36722 4609
37 C 38632774
37 B 69020351 MSFT 74915 4895
39 B 31766939 AMZN 68095 537
35 C 33801770
38 C 97928113
37 C 18478497
38 C 22458301
32 B 23865193 GOOG 17214 5337
39 S 58428610 MSFT 40922 5496
38 C 82383658
38 B 87365868 AMZN 67273 4744
39 C 97264747
39 S 19270186 GOOG 61325 8339
36 C 97787481
37 B 60562518 GOOG 17276 7618
39 C 56025615
38 S 30403521 MSFT 56407 3346
38 B 5896074 AAPL 20638 6175
38 C 82383658
39 S 16611146 AAPL 89861 9334
39 S 39308325 MSFT 44022 8719
38 S 68890961 MSFT 60802 5452
38 C 68178801
38 C 5896074
39 B 2726550 MSFT 58559 9033
37 C 64557516
39 S 85013888 AAPL 24544 6975
38 S 95546974 AMZN 78953 7194
39 B 69158063 GOOG 55199 9130
39 C 65390459
39 B 39485962 GOOG 81994 9237
37 B 54392318 GOOG 9545 4413
36 S 72173412 AMZN 39077 5922
35 S 52084138 GOOG 67256 8099
38 S 83260626 MSFT 3548 9024
38 B 93928228 AMZN 9306 6739
37 C 60562518
39 B 68189276 AMZN 41827 8629
39 C 9622824
37 S 99496988 AMZN 84200 6187
39 S 74198759 GOOG 59727 8391
39 S 17717840 AAPL 27070 9608
38 S 11209444 AMZN 90891 5426
39 S 4909740 AAPL 1650 6253
39 C 77443423
39 C 47824737
39 B 26727276 AMZN 36766 6604
38 C 35431794
39 B 74951530 GOOG 56037 1831
39 S 55958886 AMZN 90987 5134
38 S 25717370 GOOG 48774 7916
39 S 35915216 AAPL 98360 8022
39 C 30759854
39 S 95247139 MSFT 53010 786
39 B 62437792 GOOG 88109 9771
39 B 37535939 GOOG 41723 5443
38 B 1051941 MSFT 47162 6716
39 S 57035873 MSFT 6370 2506
39 S 16336981 AMZN 82989 333
39 B 53059353 MSFT 75856 5524
36 C 38488313
38 C 68890961
37 C 50404154
39 B 15451764 AAPL 82662 7763
37 B 90267568 AMZN 83373 7178
39 S 15771030 AAPL 34573 563
38 C 25717370
38 S 26797115 MSFT 29565 1113
37 C 91772595
38 C 83260626
38 B 89546186 GOOG 66534 5349
38 C 9627308
39 B 33900619 GOOG 90002 7425
39 S 60339499 AMZN 44455 9402
39 S 85604589 GOOG 77879 6369
38 C 68178801
35 S 20641501 GOOG 78134 1473
38 B 76987882 AAPL 57522 4195
39 B 87104344 AMZN 99488 8534
38 C 97928113
39 C 92976695
39 S 14355603 AAPL 70025 5769
39 B 94769706 AAPL 44732 9842
39 C 70569828
38 S 5607276 GOOG 32610 7666
37 B 60400069 MSFT 13191 7243
36 C 38488313
39 S 34594567 AMZN 47643 7368
39 C 87104344
36 S 60166406 GOOG 18157 3760
39 B 36932253 GOOG 1017 4574
31 B 99366798 AMZN 67267 3449
35 B 51657561 AMZN 80398 9995
38 B 16263600 AMZN 36548 7666
37 C 15672842
37 B 653660 AAPL 93500 3613
37 C 69020351
38 B 57876922 MSFT 57073 1786
38 C 43598460
38 S 6880898 GOOG 3398 1261
37 B 21334232 MSFT 89975 6094
37 C 13282829
38 C 25717370
38 C 83260626
38 B 87596467 MSFT 92096 9452
35 C 51657561
38 C 93928228
36 S 94740702 AAPL 51786 5489
37 B 71359849 AMZN 87283 3582
36 B 13481455 AAPL 61934 2694
36 S 48805962 AAPL 80524 6521
38 S 78195890 AMZN 34021 7970
38 B 59645335 GOOG 60497 8390
38 S 3504777 MSFT 24789 2893
36 S 46836877 AAPL 82971 7712
38 C 5896074
38 S 49582690 GOOG 48254 5104
38 S 38972101 AAPL 42885 3517
38 B 98514499 AAPL 34335 8769
35 C 20641501
37 S 74235516 GOOG 28154 1476
34 C 74083672
37 B 23381517 GOOG 14143 4714
38 C 35431794
35 S 78431382 MSFT 90814 6280
33 S 72777769 MSFT 75960 6105
38 B 80936904 GOOG 77385 3778
38 S 54028578 MSFT 10676 1792
38 B 52376959 AAPL 39293 3785
35 B 99360204 GOOG 53286 5801
36 B 85400103 AAPL 12356 4173
38 S 9316609 MSFT 16631 6120
35 S 61550278 AAPL 22615 7592
37 C 17432355
38 B 93937922 AMZN 87202 371
38 S 85147252 GOOG 88672 9036
38 B 54349067 AAPL 19373 9957
37 S 32986799 AMZN 81181 2775
37 C 72608991
38 C 45227050
38 B 34853307 AAPL 30434 5698
35 C 3247402
36 S 49759070 AAPL 31948 2042
38 S 31422840 GOOG 68411 9333
38 C 16263600
37 S 86772753 AAPL 17163 9622
38 C 22458301
38 C 25717370
36 B 5460666 AMZN 77421 8557
38 S 96784036 GOOG 75574 3989
38 S 41557088 GOOG 42659 8467
37 C 32986799
38 S 2846561 AMZN 90990 7826
37 B 15292991 MSFT 22546 5601
37 C 74235516
37 B 56796064 MSFT 84932 799
35 B 8923390 MSFT 78606 6049
38 C 52376959
38 B 78554773 AMZN 19656 9108
38 C 22458301
38 C 16263600
38 B 18180710 AAPL 82169 6218
37 S 28375444 GOOG 2793 124
36 S 22824277 GOOG 4376 7052
38 B 76638214 AMZN 73674 7995
37 S 96911838 MSFT 53017 7845
36 B 71202869 MSFT 74451 2647
37 C 32986799
36 S 22128875 GOOG 6259 5642
37 C 50404154
37 C 93968227
36 B 48539977 MSFT 84262 6490
37 S 39746802 MSFT 63769 264
35 S 6257956 AAPL 97213 1980
32 S 2004723 AAPL 21482 3291
36 B 53563097 GOOG 32325 9430
36 S 57135721 AMZN 20549 7289
37 S 68323536 GOOG 12294 6895
37 S 73042331 GOOG 31221 3787
36 S 67314253 MSFT 45451 644
36 C 65932423
37 S 68721070 AMZN 91924 112
35 C 33801770
36 S 98047387 AMZN 90150 9123
37 B 23938115 MSFT 35820 2665
37 B 36938970 AAPL 80608 3836
36 B 27619583 AAPL 17593 3633
37 S 29494263 MSFT 9429 9471
37 C 54392318
